<?xml version="1.0"?>
<robot name="steering" xmlns:xacro="https://www.ros.org/wiki/xacro">
  <xacro:macro name="steering">
    <xacro:property name="M_PI" value="3.1415926" />
    <xacro:property name="Joint_ZERO" value="0" />
    <xacro:property name="Joint_ONE" value="1" />
    <xacro:property name="Joint_Revolute" value="revolute" />
    <xacro:property name="File_Path_DAE" value="package://steering_module_description/meshes/dae" />
    <xacro:property name="File_Path_STL" value="package://steering_module_description/meshes/stl" />
    <xacro:property name="Joint_Fixed" value="fixed" />

    <link name="turn_to_link">
      <inertial>
        <origin xyz="-0.063764082051451 -0.223984714216175 -0.0252812454553025" rpy="${Joint_ZERO} ${Joint_ZERO} ${Joint_ZERO}" />
        <mass value="7.74386372914031" />
        <inertia ixx="0.0769847292516015" ixy="-0.000273654810293264" ixz="-0.0141104719774003" iyy="0.119354131568816" iyz="0.000596796086896848" izz="0.0718902740521689" />
      </inertial>
      <visual>
        <origin xyz="${Joint_ZERO} ${Joint_ZERO} ${Joint_ZERO}" rpy="${Joint_ZERO} ${Joint_ZERO} ${Joint_ZERO}" />
        <geometry>
          <mesh filename="${File_Path_DAE}/turn_to_link.dae" />
        </geometry>
        <material name="">
          <color rgba="0.890196078431372 0.890196078431372 0.913725490196078 ${Joint_ONE}" />
        </material>
      </visual>
      <collision>
        <origin xyz="${Joint_ZERO} ${Joint_ZERO} ${Joint_ZERO}" rpy="${Joint_ZERO} ${Joint_ZERO} ${Joint_ZERO}" />
        <geometry>
          <mesh filename="${File_Path_STL}/turn_to_link.stl" />
        </geometry>
      </collision>
    </link>

    <link name="driving_gear_link">
      <inertial>
        <origin xyz="0.010011 -0.00018607 -1.0304E-09" rpy="${Joint_ZERO} ${Joint_ZERO} ${Joint_ZERO}" />
        <mass value="0.018843" />
        <inertia ixx="4.7506E-06" ixy="-3.8571E-11" ixz="-4.2541E-15" iyy="3.0138E-06" iyz="3.8641E-13" izz="2.9764E-06" />
      </inertial>
      <visual>
        <origin xyz="${Joint_ZERO} ${Joint_ZERO} ${Joint_ZERO}" rpy="${Joint_ZERO} ${Joint_ZERO} ${Joint_ZERO}" />
        <geometry>
          <mesh filename="${File_Path_DAE}/driving_gear_link.dae" />
        </geometry>
        <material name="">
          <color rgba="0.79216 0.81961 0.93333  ${Joint_ONE}" />
        </material>
      </visual>
      <collision>
        <origin xyz="${Joint_ZERO} ${Joint_ZERO} ${Joint_ZERO}" rpy="${Joint_ZERO} ${Joint_ZERO} ${Joint_ZERO}" />
        <geometry>
          <mesh filename="${File_Path_STL}/driving_gear_link.stl" />
        </geometry>
      </collision>
    </link>
    <joint name="joint_driving_gear" type="continuous">
      <origin xyz="-0.15141 -0.28522 -0.022722" rpy="${M_PI/2} 0 -${M_PI/2}"></origin>
      <parent link="turn_to_link" />
      <child link="driving_gear_link" />
      <axis xyz="${Joint_ONE} ${Joint_ZERO} ${Joint_ZERO} " />
    </joint>

    <link name="driven_gear_link">
      <inertial>
        <origin xyz="3.89265716754308E-05 1.62060078654769E-05 0.0162446027714712" rpy="${Joint_ZERO} ${Joint_ZERO} ${Joint_ZERO}" />
        <mass value="1.84024058367429" />
        <inertia ixx="0.00398005621390154" ixy="1.20915509078338E-06" ixz="-6.97309341864162E-07" iyy="0.00397765652813965" iyz="-2.87952744651294E-07" izz="0.00766666066271265" />
      </inertial>
      <visual>
        <origin xyz="${Joint_ZERO} ${Joint_ZERO} ${Joint_ZERO}" rpy="${Joint_ZERO} ${Joint_ZERO} ${Joint_ZERO}" />
        <geometry>
          <mesh filename="${File_Path_DAE}/driven_gear_link.dae" />
        </geometry>
        <material name="">
          <color rgba="0.776470588235294 0.756862745098039 0.737254901960784 ${Joint_ONE}" />
        </material>
      </visual>
      <collision>
        <origin xyz="${Joint_ZERO} ${Joint_ZERO} ${Joint_ZERO}" rpy="${Joint_ZERO} ${Joint_ZERO} ${Joint_ZERO}" />
        <geometry>
          <mesh filename="${File_Path_STL}/driven_gear_link.stl" />
        </geometry>
      </collision>
    </link>
    <joint name="joint_driven_gear" type="${Joint_Revolute}">
      <origin xyz="-0.082469 -0.28422 -0.080572" rpy="-${M_PI/2} -0.3927 -${M_PI}" />
      <parent link="turn_to_link" />
      <child link="driven_gear_link" />
      <axis xyz="${Joint_ZERO} ${Joint_ZERO} ${Joint_ONE}" />
      <limit effort="30" velocity="1.0" lower="-${M_PI/2}" upper="${M_PI/2}" />
    </joint>
  </xacro:macro>
</robot>
